<robot name = "robot">
    <link name="0">
        <inertial>
            <origin xyz="0 0 0.25" rpy="0 0 0"/>
            <mass value="1" />
            <inertia ixx="100" ixy="0" ixz="0" iyy="100" iyz="0" izz="100" />
        </inertial>
        <visual>
            <origin xyz="0 0 0.25" rpy="0 0 0"/>
            <geometry>
                <box size="0.5 0.5 0.5" />
            </geometry>
            <material name="Cyan">
                <color rgba="0 1.0 1.0 1.0"/>
            </material>
        </visual>
        <collision>
            <origin xyz="0 0 0.25" rpy="0 0 0"/>
            <geometry>
                <box size="0.5 0.5 0.5" />
            </geometry>
        </collision>
    </link>
    <joint name="0_1" type="revolute">
       <parent link="0"/>
       <child  link="1"/>
       <origin rpy="0 0 0" xyz="0 0.25 0.25" />
     <axis xyz="1 0 0"/>
       <limit effort="0.0" lower="-3.14159" upper="3.14159" velocity="0.0"/>
    </joint>
    <link name="1">
        <inertial>
            <origin xyz="0 0.10561201317501034 0" rpy="0 0 0"/>
            <mass value="1" />
            <inertia ixx="100" ixy="0" ixz="0" iyy="100" iyz="0" izz="100" />
        </inertial>
        <visual>
            <origin xyz="0 0.10561201317501034 0" rpy="0 0 0"/>
            <geometry>
                <box size="0.8865239289829635 0.2112240263500207 0.0571746665611349" />
            </geometry>
            <material name="Green">
                <color rgba="0 1.0 0.0 1.0"/>
            </material>
        </visual>
        <collision>
            <origin xyz="0 0.10561201317501034 0" rpy="0 0 0"/>
            <geometry>
                <box size="0.8865239289829635 0.2112240263500207 0.0571746665611349" />
            </geometry>
        </collision>
    </link>
    <joint name="1_2" type="revolute">
       <parent link="1"/>
       <child  link="2"/>
       <origin rpy="0 0 0" xyz="0 0.2112240263500207 0" />
     <axis xyz="1 0 0"/>
       <limit effort="0.0" lower="-3.14159" upper="3.14159" velocity="0.0"/>
    </joint>
    <link name="2">
        <inertial>
            <origin xyz="0 0.3392828966519622 0" rpy="0 0 0"/>
            <mass value="1" />
            <inertia ixx="100" ixy="0" ixz="0" iyy="100" iyz="0" izz="100" />
        </inertial>
        <visual>
            <origin xyz="0 0.3392828966519622 0" rpy="0 0 0"/>
            <geometry>
                <box size="0.8116695771452592 0.6785657933039244 0.5549650964993414" />
            </geometry>
            <material name="Cyan">
                <color rgba="0 1.0 1.0 1.0"/>
            </material>
        </visual>
        <collision>
            <origin xyz="0 0.3392828966519622 0" rpy="0 0 0"/>
            <geometry>
                <box size="0.8116695771452592 0.6785657933039244 0.5549650964993414" />
            </geometry>
        </collision>
    </link>
    <joint name="2_3" type="revolute">
       <parent link="2"/>
       <child  link="3"/>
       <origin rpy="0 0 0" xyz="0 0.6785657933039244 0" />
     <axis xyz="1 0 0"/>
       <limit effort="0.0" lower="-3.14159" upper="3.14159" velocity="0.0"/>
    </joint>
    <link name="3">
        <inertial>
            <origin xyz="0 0.15160099024623974 0" rpy="0 0 0"/>
            <mass value="1" />
            <inertia ixx="100" ixy="0" ixz="0" iyy="100" iyz="0" izz="100" />
        </inertial>
        <visual>
            <origin xyz="0 0.15160099024623974 0" rpy="0 0 0"/>
            <geometry>
                <box size="0.19021702967088805 0.3032019804924795 0.3256115366170601" />
            </geometry>
            <material name="Cyan">
                <color rgba="0 1.0 1.0 1.0"/>
            </material>
        </visual>
        <collision>
            <origin xyz="0 0.15160099024623974 0" rpy="0 0 0"/>
            <geometry>
                <box size="0.19021702967088805 0.3032019804924795 0.3256115366170601" />
            </geometry>
        </collision>
    </link>
    <joint name="3_4" type="revolute">
       <parent link="3"/>
       <child  link="4"/>
       <origin rpy="0 0 0" xyz="0 0.3032019804924795 0" />
     <axis xyz="1 0 0"/>
       <limit effort="0.0" lower="-3.14159" upper="3.14159" velocity="0.0"/>
    </joint>
    <link name="4">
        <inertial>
            <origin xyz="0 0.04938317249921664 0" rpy="0 0 0"/>
            <mass value="1" />
            <inertia ixx="100" ixy="0" ixz="0" iyy="100" iyz="0" izz="100" />
        </inertial>
        <visual>
            <origin xyz="0 0.04938317249921664 0" rpy="0 0 0"/>
            <geometry>
                <box size="0.30717453263971684 0.09876634499843329 0.9244109455478576" />
            </geometry>
            <material name="Cyan">
                <color rgba="0 1.0 1.0 1.0"/>
            </material>
        </visual>
        <collision>
            <origin xyz="0 0.04938317249921664 0" rpy="0 0 0"/>
            <geometry>
                <box size="0.30717453263971684 0.09876634499843329 0.9244109455478576" />
            </geometry>
        </collision>
    </link>
</robot>