<robot name = "robot">
    <link name="Torso0">
        <inertial>
            <origin xyz="1 0 1.5" rpy="0 0 0"/>
            <mass value="1" />
            <inertia ixx="100" ixy="0" ixz="0" iyy="100" iyz="0" izz="100" />
        </inertial>
        <visual>
            <origin xyz="1 0 1.5" rpy="0 0 0"/>
            <geometry>
                <box size="4 1 1" />
            </geometry>
            <material name="Cyan">
                <color rgba="0 1.0 1.0 1.0"/>
            </material>
        </visual>
        <collision>
            <origin xyz="1 0 1.5" rpy="0 0 0"/>
            <geometry>
                <box size="4 1 1" />
            </geometry>
        </collision>
    </link>
    <joint name="Torso0_Torso0Leg1" type="revolute">
       <parent link="Torso0"/>
       <child  link="Torso0Leg1"/>
       <origin rpy="0 0 0" xyz="0.5 0 1" />
     <axis xyz="1 0 0"/>
       <limit effort="0.0" lower="-3.14159" upper="3.14159" velocity="0.0"/>
    </joint>
    <link name="Torso0Leg1">
        <inertial>
            <origin xyz="-0.5 0 -0.5" rpy="0 0 0"/>
            <mass value="1" />
            <inertia ixx="100" ixy="0" ixz="0" iyy="100" iyz="0" izz="100" />
        </inertial>
        <visual>
            <origin xyz="-0.5 0 -0.5" rpy="0 0 0"/>
            <geometry>
                <box size="0.5381811430341946 1 1" />
            </geometry>
            <material name="Green">
                <color rgba="0 1.0 0.0 1.0"/>
            </material>
        </visual>
        <collision>
            <origin xyz="-0.5 0 -0.5" rpy="0 0 0"/>
            <geometry>
                <box size="0.5381811430341946 1 1" />
            </geometry>
        </collision>
    </link>
    <joint name="Torso0_Torso0Leg2" type="revolute">
       <parent link="Torso0"/>
       <child  link="Torso0Leg2"/>
       <origin rpy="0 0 0" xyz="1.5 0 1" />
     <axis xyz="1 0 0"/>
       <limit effort="0.0" lower="-3.14159" upper="3.14159" velocity="0.0"/>
    </joint>
    <link name="Torso0Leg2">
        <inertial>
            <origin xyz="0.5 0 -0.5" rpy="0 0 0"/>
            <mass value="1" />
            <inertia ixx="100" ixy="0" ixz="0" iyy="100" iyz="0" izz="100" />
        </inertial>
        <visual>
            <origin xyz="0.5 0 -0.5" rpy="0 0 0"/>
            <geometry>
                <box size="0.24975467367338686 1 1" />
            </geometry>
            <material name="Green">
                <color rgba="0 1.0 0.0 1.0"/>
            </material>
        </visual>
        <collision>
            <origin xyz="0.5 0 -0.5" rpy="0 0 0"/>
            <geometry>
                <box size="0.24975467367338686 1 1" />
            </geometry>
        </collision>
    </link>
    <joint name="Torso0_Torso0Leg3" type="revolute">
       <parent link="Torso0"/>
       <child  link="Torso0Leg3"/>
       <origin rpy="0 0 0" xyz="0.75 0 1" />
     <axis xyz="1 0 0"/>
       <limit effort="0.0" lower="-3.14159" upper="3.14159" velocity="0.0"/>
    </joint>
    <link name="Torso0Leg3">
        <inertial>
            <origin xyz="0 0 -0.5" rpy="0 0 0"/>
            <mass value="1" />
            <inertia ixx="100" ixy="0" ixz="0" iyy="100" iyz="0" izz="100" />
        </inertial>
        <visual>
            <origin xyz="0 0 -0.5" rpy="0 0 0"/>
            <geometry>
                <box size="0.9960176754775214 1 1" />
            </geometry>
            <material name="Green">
                <color rgba="0 1.0 0.0 1.0"/>
            </material>
        </visual>
        <collision>
            <origin xyz="0 0 -0.5" rpy="0 0 0"/>
            <geometry>
                <box size="0.9960176754775214 1 1" />
            </geometry>
        </collision>
    </link>
    <joint name="Torso0_Torso0Leg5" type="revolute">
       <parent link="Torso0"/>
       <child  link="Torso0Leg5"/>
       <origin rpy="0 0 0" xyz="2 0 1" />
     <axis xyz="1 0 0"/>
       <limit effort="0.0" lower="-3.14159" upper="3.14159" velocity="0.0"/>
    </joint>
    <link name="Torso0Leg5">
        <inertial>
            <origin xyz="1 0 -0.5" rpy="0 0 0"/>
            <mass value="1" />
            <inertia ixx="100" ixy="0" ixz="0" iyy="100" iyz="0" izz="100" />
        </inertial>
        <visual>
            <origin xyz="1 0 -0.5" rpy="0 0 0"/>
            <geometry>
                <box size="0.5201716842271491 1 1" />
            </geometry>
            <material name="Cyan">
                <color rgba="0 1.0 1.0 1.0"/>
            </material>
        </visual>
        <collision>
            <origin xyz="1 0 -0.5" rpy="0 0 0"/>
            <geometry>
                <box size="0.5201716842271491 1 1" />
            </geometry>
        </collision>
    </link>
    <joint name="Torso1_Torso0" type="revolute">
       <parent link="Torso1"/>
       <child  link="Torso0"/>
       <origin rpy="0 0 0" xyz="0 4 0" />
     <axis xyz="1 0 0"/>
       <limit effort="0.0" lower="-3.14159" upper="3.14159" velocity="0.0"/>
    </joint>
    <link name="Torso1">
        <inertial>
            <origin xyz="2 2 0" rpy="0 0 0"/>
            <mass value="1" />
            <inertia ixx="100" ixy="0" ixz="0" iyy="100" iyz="0" izz="100" />
        </inertial>
        <visual>
            <origin xyz="2 2 0" rpy="0 0 0"/>
            <geometry>
                <box size="4 1 1" />
            </geometry>
            <material name="Cyan">
                <color rgba="0 1.0 1.0 1.0"/>
            </material>
        </visual>
        <collision>
            <origin xyz="2 2 0" rpy="0 0 0"/>
            <geometry>
                <box size="4 1 1" />
            </geometry>
        </collision>
    </link>
    <joint name="Torso1_Torso1Leg1" type="revolute">
       <parent link="Torso1"/>
       <child  link="Torso1Leg1"/>
       <origin rpy="0 0 0" xyz="0.5 0 1" />
     <axis xyz="1 0 0"/>
       <limit effort="0.0" lower="-3.14159" upper="3.14159" velocity="0.0"/>
    </joint>
    <link name="Torso1Leg1">
        <inertial>
            <origin xyz="3.5 0 -0.5" rpy="0 0 0"/>
            <mass value="1" />
            <inertia ixx="100" ixy="0" ixz="0" iyy="100" iyz="0" izz="100" />
        </inertial>
        <visual>
            <origin xyz="3.5 0 -0.5" rpy="0 0 0"/>
            <geometry>
                <box size="0.713736848724658 1 1" />
            </geometry>
            <material name="Green">
                <color rgba="0 1.0 0.0 1.0"/>
            </material>
        </visual>
        <collision>
            <origin xyz="3.5 0 -0.5" rpy="0 0 0"/>
            <geometry>
                <box size="0.713736848724658 1 1" />
            </geometry>
        </collision>
    </link>
    <joint name="Torso1_Torso1Leg2" type="revolute">
       <parent link="Torso1"/>
       <child  link="Torso1Leg2"/>
       <origin rpy="0 0 0" xyz="1.5 0 1" />
     <axis xyz="1 0 0"/>
       <limit effort="0.0" lower="-3.14159" upper="3.14159" velocity="0.0"/>
    </joint>
    <link name="Torso1Leg2">
        <inertial>
            <origin xyz="0.5 0 -0.5" rpy="0 0 0"/>
            <mass value="1" />
            <inertia ixx="100" ixy="0" ixz="0" iyy="100" iyz="0" izz="100" />
        </inertial>
        <visual>
            <origin xyz="0.5 0 -0.5" rpy="0 0 0"/>
            <geometry>
                <box size="0.49605478257826974 1 1" />
            </geometry>
            <material name="Green">
                <color rgba="0 1.0 0.0 1.0"/>
            </material>
        </visual>
        <collision>
            <origin xyz="0.5 0 -0.5" rpy="0 0 0"/>
            <geometry>
                <box size="0.49605478257826974 1 1" />
            </geometry>
        </collision>
    </link>
    <joint name="Torso1_Torso1Leg4" type="revolute">
       <parent link="Torso1"/>
       <child  link="Torso1Leg4"/>
       <origin rpy="0 0 0" xyz="0 0 1" />
     <axis xyz="1 0 0"/>
       <limit effort="0.0" lower="-3.14159" upper="3.14159" velocity="0.0"/>
    </joint>
    <link name="Torso1Leg4">
        <inertial>
            <origin xyz="-1 0 -0.5" rpy="0 0 0"/>
            <mass value="1" />
            <inertia ixx="100" ixy="0" ixz="0" iyy="100" iyz="0" izz="100" />
        </inertial>
        <visual>
            <origin xyz="-1 0 -0.5" rpy="0 0 0"/>
            <geometry>
                <box size="0.5164878030918523 1 1" />
            </geometry>
            <material name="Cyan">
                <color rgba="0 1.0 1.0 1.0"/>
            </material>
        </visual>
        <collision>
            <origin xyz="-1 0 -0.5" rpy="0 0 0"/>
            <geometry>
                <box size="0.5164878030918523 1 1" />
            </geometry>
        </collision>
    </link>
</robot>