<robot name = "robot">
    <link name="Torso0">
        <inertial>
            <origin xyz="1 0 1.5" rpy="0 0 0"/>
            <mass value="1" />
            <inertia ixx="100" ixy="0" ixz="0" iyy="100" iyz="0" izz="100" />
        </inertial>
        <visual>
            <origin xyz="1 0 1.5" rpy="0 0 0"/>
            <geometry>
                <box size="4 1 1" />
            </geometry>
            <material name="Cyan">
                <color rgba="0 1.0 1.0 1.0"/>
            </material>
        </visual>
        <collision>
            <origin xyz="1 0 1.5" rpy="0 0 0"/>
            <geometry>
                <box size="4 1 1" />
            </geometry>
        </collision>
    </link>
    <joint name="Torso0_Torso0Leg1" type="revolute">
       <parent link="Torso0"/>
       <child  link="Torso0Leg1"/>
       <origin rpy="0 0 0" xyz="0.5 0 1" />
     <axis xyz="1 0 0"/>
       <limit effort="0.0" lower="-3.14159" upper="3.14159" velocity="0.0"/>
    </joint>
    <link name="Torso0Leg1">
        <inertial>
            <origin xyz="-0.5 0 -0.5" rpy="0 0 0"/>
            <mass value="1" />
            <inertia ixx="100" ixy="0" ixz="0" iyy="100" iyz="0" izz="100" />
        </inertial>
        <visual>
            <origin xyz="-0.5 0 -0.5" rpy="0 0 0"/>
            <geometry>
                <box size="0.6530529199529767 1 1" />
            </geometry>
            <material name="Green">
                <color rgba="0 1.0 0.0 1.0"/>
            </material>
        </visual>
        <collision>
            <origin xyz="-0.5 0 -0.5" rpy="0 0 0"/>
            <geometry>
                <box size="0.6530529199529767 1 1" />
            </geometry>
        </collision>
    </link>
    <joint name="Torso0_Torso0Leg2" type="revolute">
       <parent link="Torso0"/>
       <child  link="Torso0Leg2"/>
       <origin rpy="0 0 0" xyz="1.5 0 1" />
     <axis xyz="1 0 0"/>
       <limit effort="0.0" lower="-3.14159" upper="3.14159" velocity="0.0"/>
    </joint>
    <link name="Torso0Leg2">
        <inertial>
            <origin xyz="0.5 0 -0.5" rpy="0 0 0"/>
            <mass value="1" />
            <inertia ixx="100" ixy="0" ixz="0" iyy="100" iyz="0" izz="100" />
        </inertial>
        <visual>
            <origin xyz="0.5 0 -0.5" rpy="0 0 0"/>
            <geometry>
                <box size="0.8469391870576657 1 1" />
            </geometry>
            <material name="Cyan">
                <color rgba="0 1.0 1.0 1.0"/>
            </material>
        </visual>
        <collision>
            <origin xyz="0.5 0 -0.5" rpy="0 0 0"/>
            <geometry>
                <box size="0.8469391870576657 1 1" />
            </geometry>
        </collision>
    </link>
    <joint name="Torso0_Torso0Leg3" type="revolute">
       <parent link="Torso0"/>
       <child  link="Torso0Leg3"/>
       <origin rpy="0 0 0" xyz="0.75 0 1" />
     <axis xyz="1 0 0"/>
       <limit effort="0.0" lower="-3.14159" upper="3.14159" velocity="0.0"/>
    </joint>
    <link name="Torso0Leg3">
        <inertial>
            <origin xyz="0 0 -0.5" rpy="0 0 0"/>
            <mass value="1" />
            <inertia ixx="100" ixy="0" ixz="0" iyy="100" iyz="0" izz="100" />
        </inertial>
        <visual>
            <origin xyz="0 0 -0.5" rpy="0 0 0"/>
            <geometry>
                <box size="0.3570065176206738 1 1" />
            </geometry>
            <material name="Cyan">
                <color rgba="0 1.0 1.0 1.0"/>
            </material>
        </visual>
        <collision>
            <origin xyz="0 0 -0.5" rpy="0 0 0"/>
            <geometry>
                <box size="0.3570065176206738 1 1" />
            </geometry>
        </collision>
    </link>
    <joint name="Torso0_Torso0Leg5" type="revolute">
       <parent link="Torso0"/>
       <child  link="Torso0Leg5"/>
       <origin rpy="0 0 0" xyz="2 0 1" />
     <axis xyz="1 0 0"/>
       <limit effort="0.0" lower="-3.14159" upper="3.14159" velocity="0.0"/>
    </joint>
    <link name="Torso0Leg5">
        <inertial>
            <origin xyz="1 0 -0.5" rpy="0 0 0"/>
            <mass value="1" />
            <inertia ixx="100" ixy="0" ixz="0" iyy="100" iyz="0" izz="100" />
        </inertial>
        <visual>
            <origin xyz="1 0 -0.5" rpy="0 0 0"/>
            <geometry>
                <box size="0.46556820524323506 1 1" />
            </geometry>
            <material name="Cyan">
                <color rgba="0 1.0 1.0 1.0"/>
            </material>
        </visual>
        <collision>
            <origin xyz="1 0 -0.5" rpy="0 0 0"/>
            <geometry>
                <box size="0.46556820524323506 1 1" />
            </geometry>
        </collision>
    </link>
</robot>